<?xml version="1.0" ?>
<!-- =================================================================================== -->
<!-- |    This document was autogenerated by xacro from turtlebot3_burger.urdf         | -->
<!-- |    EDITING THIS FILE BY HAND IS NOT RECOMMENDED                                 | -->
<!-- =================================================================================== -->
<robot name="turtlebot3_burger">
  <!-- <xacro:include filename="$(find turtlebot3_descriptions)/urdf/common_properties.urdf"/> -->
  <!-- Init colour -->
  <material name="black">
    <color rgba="0.0 0.0 0.0 1.0"/>
  </material>
  <material name="dark">
    <color rgba="0.3 0.3 0.3 1.0"/>
  </material>
  <material name="light_black">
    <color rgba="0.4 0.4 0.4 1.0"/>
  </material>
  <material name="blue">
    <color rgba="0.0 0.0 0.8 1.0"/>
  </material>
  <material name="green">
    <color rgba="0.0 0.8 0.0 1.0"/>
  </material>
  <material name="grey">
    <color rgba="0.5 0.5 0.5 1.0"/>
  </material>
  <material name="orange">
    <color rgba="1.0 0.4235 0.0392 1.0"/>
  </material>
  <material name="brown">
    <color rgba="0.8706 0.8118 0.7647 1.0"/>
  </material>
  <material name="red">
    <color rgba="0.8 0.0 0.0 1.0"/>
  </material>
  <material name="white">
    <color rgba="1.0 1.0 1.0 1.0"/>
  </material>
  <link name="base_footprint"/>
  <joint name="base_joint" type="fixed">
    <parent link="base_footprint"/>
    <child link="base_link"/>
    <origin rpy="0 0 0" xyz="0.0 0.0 0.010"/>
  </joint>
  <link name="base_link">
    <visual>
      <origin rpy="0 0 0" xyz="-0.032 0 0.0"/>
      <geometry>
        <mesh filename="package://turtlebot3_descriptions/meshes/bases/burger_base.stl" scale="0.001 0.001 0.001"/>
      </geometry>
      <material name="light_black"/>
    </visual>
    <collision>
      <origin rpy="0 0 0" xyz="-0.032 0 0.070"/>
      <geometry>
        <box size="0.140 0.140 0.143"/>
      </geometry>
    </collision>
    <inertial>
      <origin rpy="0 0 0" xyz="-0.033 0 0.07"/>
      <mass value="8.2573504e-01"/>
      <inertia ixx="2.2124416e-03" ixy="0.0" ixz="0.0" iyy="2.1193702e-03" iyz="0.0" izz="2.0064271e-03"/>
    </inertial>
  </link>
  <joint name="wheel_left_joint" type="continuous">
    <parent link="base_link"/>
    <child link="wheel_left_link"/>
    <origin rpy="-1.57 0 0" xyz="0.0 0.08 0.023"/>
    <axis xyz="0 0 1"/>
  </joint>
  <link name="wheel_left_link">
    <visual>
      <origin rpy="1.57 0 0" xyz="0 0 0"/>
      <geometry>
        <mesh filename="package://turtlebot3_descriptions/meshes/wheels/left_tire.stl" scale="0.001 0.001 0.001"/>
      </geometry>
      <material name="dark"/>
    </visual>
    <collision>
      <origin rpy="0 0 0" xyz="0 0 0"/>
      <geometry>
        <cylinder length="0.018" radius="0.033"/>
      </geometry>
    </collision>
    <inertial>
      <origin xyz="0 0 0"/>
      <mass value="2.8498940e-02"/>
      <inertia ixx="1.1175580e-05" ixy="0.0" ixz="0.0" iyy="1.1192413e-05" iyz="0.0" izz="2.0712558e-05"/>
    </inertial>
  </link>
  <joint name="wheel_right_joint" type="continuous">
    <parent link="base_link"/>
    <child link="wheel_right_link"/>
    <origin rpy="-1.57 0 0" xyz="0.0 -0.080 0.023"/>
    <axis xyz="0 0 1"/>
  </joint>
  <link name="wheel_right_link">
    <visual>
      <origin rpy="1.57 0 0" xyz="0 0 0"/>
      <geometry>
        <mesh filename="package://turtlebot3_descriptions/meshes/wheels/right_tire.stl" scale="0.001 0.001 0.001"/>
      </geometry>
      <material name="dark"/>
    </visual>
    <collision>
      <origin rpy="0 0 0" xyz="0 0 0"/>
      <geometry>
        <cylinder length="0.018" radius="0.033"/>
      </geometry>
    </collision>
    <inertial>
      <origin xyz="0 0 0"/>
      <mass value="2.8498940e-02"/>
      <inertia ixx="1.1175580e-05" ixy="0.0" ixz="0.0" iyy="1.1192413e-05" iyz="0.0" izz="2.0712558e-05"/>
    </inertial>
  </link>
  <joint name="caster_back_joint" type="fixed">
    <parent link="base_link"/>
    <child link="caster_back_link"/>
    <origin rpy="-1.57 0 0" xyz="-0.081 0 -0.004"/>
  </joint>
  <link name="caster_back_link">
    <collision>
      <origin rpy="0 0 0" xyz="0 0.001 0"/>
      <geometry>
        <box size="0.030 0.009 0.020"/>
      </geometry>
    </collision>
    <inertial>
      <origin xyz="0 0 0"/>
      <mass value="0.005"/>
      <inertia ixx="1.0e-07" ixy="0.0" ixz="0.0" iyy="1.0e-07" iyz="0.0" izz="1.0e-07"/>
    </inertial>
  </link>
  <joint name="imu_joint" type="fixed">
    <parent link="base_link"/>
    <child link="imu_link"/>
    <origin rpy="0 0 0" xyz="-0.032 0 0.068"/>
  </joint>
  <link name="imu_link"/>
  <joint name="scan_joint" type="fixed">
    <parent link="base_link"/>
    <child link="base_scan"/>
    <origin rpy="0 0 0" xyz="-0.032 0 0.172"/>
  </joint>
  <link name="base_scan">
    <visual>
      <origin rpy="0 0 0" xyz="0 0 0.0"/>
      <geometry>
        <mesh filename="package://turtlebot3_descriptions/meshes/sensors/lds.stl" scale="0.001 0.001 0.001"/>
      </geometry>
      <material name="dark"/>
    </visual>
    <collision>
      <origin rpy="0 0 0" xyz="0.015 0 -0.0065"/>
      <geometry>
        <cylinder length="0.0315" radius="0.055"/>
      </geometry>
    </collision>
    <inertial>
      <mass value="0.114"/>
      <origin xyz="0 0 -0.01"/>
      <inertia ixx="47.43e-06" ixy="0.0" ixz="0.0" iyy="79.51e-06" iyz="0.0" izz="102.75e-06"/>
    </inertial>
  </link>

  <link name="base_gripper">
    <visual>
      <origin rpy="0 0 0" xyz="0 0 0.0"/>
      <geometry>
        <mesh filename="package://turtlebot3_descriptions/meshes/actuators/gripper/gripper_base.stl" scale="0.001 0.001 0.001"/>
      </geometry>
      <material name="dark"/>
    </visual>
    <collision>
      <origin rpy="0 0 0" xyz="0 0 -0.01"/>
      <geometry>
        <box size="0.03 0.055 0.06"/>
      </geometry>
    </collision>
    <inertial>
       <origin xyz="0 0 0"/>
       <mass value="0.06"/>
       <inertia ixx="23.84e-06" ixy="0.0" ixz="0.0" iyy="16.238e-06" iyz="0.0" izz="13.47e-06"/>
    </inertial>
  </link>
  <joint name="gripper_base_joint" type="fixed">
    <parent link="base_link"/>
    <child link="base_gripper"/>
    <origin rpy="0 0 0" xyz="0.052 0.0025 0.04"/>
  </joint>

  <link name="tilt_gripper">
    <visual>
      <origin rpy="0 0 0" xyz="0 0 0.0"/>
      <geometry>
        <mesh filename="package://turtlebot3_descriptions/meshes/actuators/gripper/gripper_tilt.stl" scale="0.001 0.001 0.001"/>
      </geometry>
      <material name="dark"/>
    </visual>
    <collision>
      <origin rpy="0 0 0" xyz="0.045 0 0"/>
      <geometry>
        <box size="0.055 0.075 0.06"/>
      </geometry>
    </collision>
    <inertial>
        <origin xyz="0.025 0 0"/>
        <mass value="0.06000000"/>
        <inertia ixx="23.15e-06" ixy="0.0" ixz="0.0" iyy="32.9e-06" iyz="0.0" izz="42.567e-06"/>
    </inertial>
  </link>
  <joint name="gripper_tilt_joint" type="revolute">
      <axis xyz="0 1 0"/>
      <limit effort="1000.0" lower="-0.3" upper="0" velocity="0.5"/>
      <origin rpy="0 0 0" xyz="0 0.002 0"/>
      <parent link="base_gripper"/>
      <child link="tilt_gripper"/>
  </joint>

  <link name="left_gripper">
    <visual>
      <origin rpy="0 0 0" xyz="0 0 0.0"/>
      <geometry>
        <mesh filename="package://turtlebot3_descriptions/meshes/actuators/gripper/gripper_left.stl" scale="0.001 0.001 0.001"/>
      </geometry>
      <material name="dark"/>
    </visual>
    <collision>
      <origin rpy="0 0 0" xyz="0.09 0 -0.02"/>
      <geometry>
        <box size="0.02 0.02 0.041"/>
      </geometry>
    </collision>
    <inertial>
        <origin xyz="0.045 0 -0.021"/>
        <mass value="0.12000000"/>
        <inertia ixx="23.07e-06" ixy="0.0" ixz="0.0" iyy="107.0e-06" iyz="0.0" izz="96.06e-06"/>
    </inertial>
  </link>
  <joint name="gripper_left_joint" type="revolute">
      <axis xyz="0 0 1"/>
      <limit effort="1000.0" lower="0" upper="1.0" velocity="0.5"/>
      <origin rpy="0 0 0" xyz="0.05 0.016 0.018"/>
      <parent link="tilt_gripper"/>
      <child link="left_gripper"/>
  </joint>

  <link name="right_gripper">
    <visual>
      <origin rpy="0 0 0" xyz="0 0 0.0"/>
      <geometry>
        <mesh filename="package://turtlebot3_descriptions/meshes/actuators/gripper/gripper_right.stl" scale="0.001 0.001 0.001"/>
      </geometry>
      <material name="dark"/>
    </visual>
    <collision>
      <origin rpy="0 0 0" xyz="0.09 0 -0.02"/>
      <geometry>
        <box size="0.02 0.02 0.041"/>
      </geometry>
    </collision>
    <inertial>
        <origin xyz="0.045 0.0 -0.021"/>
        <mass value="0.12000000"/>
        <inertia ixx="23.20e-06" ixy="0.0" ixz="0.0" iyy="107.33e-06" iyz="0.0" izz="96.18e-06"/>
    </inertial>
  </link>
  <joint name="gripper_right_joint" type="revolute">
      <axis xyz="0 0 1"/>
      <limit effort="1000.0" lower="-1.0" upper="0" velocity="0.5"/>
      <origin rpy="0 0 0" xyz="0.05 -0.016 0.018"/>
      <parent link="tilt_gripper"/>
      <child link="right_gripper"/>
  </joint>
</robot>
